Workbook

Sheet Start Here
A1: UB College Tracker | Class of 2027
A2: University Bridges | DeKalb County Department of Youth Services | Tracker for Aaliyah Hilton
B4: HOW IT WORKS
B5: 1. Explore | C5: Browse about 200 colleges. Each one is labeled Likely, Target or Reach for you, based on your GPA and SAT. Use the filter arrows to sort and narrow.
B6: 2. My Colleges | C6: Pick a college from the dropdown (or type one that is not listed) and choose your round. Deadlines, fees and requirements fill in by themselves.
B7: 3. Next Steps | C7: Every college you add gets its own checklist with due dates counted back from its real deadline. Check each step off as you finish it.
B8: 4. This Week | C8: Your UB plan for every Thursday session, plus your next 10 college steps in date order.
B9: 5. Essays | C9: Your personal statement, your two main essays, and every extra essay prompt from your colleges, pulled in automatically.
B10: 6. Money | C10: Scholarships, and in spring, comparing award letters.
B11: 7. Me | C11: Your profile, account usernames and recommenders.
B13: COLORS
B14: White cells | C14: Type here or use the dropdown.
B15: Gray cells | C15: Fill in automatically. Do not type over them.
B16: Red row | C16: Past due and not done.
B17: Orange row | C17: Due in the next 7 days.
B19: RULES THAT DO NOT BEND
B20: Earliest date wins | C20: If a college's scholarship deadline is earlier than its application deadline, the scholarship date is your real deadline. The tracker uses it automatically.
B21: Early Decision is binding | C21: If admitted Early Decision you must attend and withdraw every other application. Only one Early Decision can be active at a time.
B22: Verify every date | C22: Deadline Verified stays No until you check the date on the college's own website. Some dates in the list are last year's pattern.
B23: Personal statement first | C23: Get your personal statement to a near-final draft before you start any college's extra essays.
B24: Never delete or reorder | C24: To drop a college, set On Final List to No. Deleting or moving rows mixes up your checklists.
B25: No passwords | C25: Never type a password anywhere in this tracker.
B26: Every Sunday | C26: Check off what you finished and type the date in the Last updated box on This Week.

Sheet This Week
A1: This Week
A2: Top: your next 10 college steps, in date order, pulled from Next Steps (check them off there). Bottom: your UB plan, one block per Thursday session. Every Sunday: check off what you finished and type today's date in Last updated.
A4: College steps overdue | B4: College steps due in 7 days | C4: UB tasks overdue | D4: UB tasks due in 7 days | F4: LAST UPDATED: type today's date every Sunday
A5: ='Next Steps'!A5 -> 0 | B5: ='Next Steps'!C5 -> 0 | C5: =SUMPRODUCT(ISNUMBER($A$22:$A$78)*($A$22:$A$78<TODAY())*($E$22:$E$78<>TRUE())*($D$22:$D$78<>"")) -> 0 | D5: =SUMPRODUCT(ISNUMBER($A$22:$A$78)*($A$22:$A$78>=TODAY())*($A$22:$A$78<=TODAY()+7)*($E$22:$E$78<>TRUE())*($D$22:$D$78<>"")) -> 12
A8: Due | B8: Days Out | C8: College | D8: Step
A9: =IF($H9="","",INT($H9)) | B9: =IF($A9="","",$A9-TODAY()) | C9: =IF($H9="","",INDEX('Next Steps'!$A$8:$A$27,SUMPRODUCT(('Next Steps'!$AE$8:$AP$27=$H9)*(ROW('Next Steps'!$AE$8:$AP$27)-7)))) | D9: =IF($H9="","",INDEX('Next Steps'!$AE$6:$AP$6,SUMPRODUCT(('Next Steps'!$AE$8:$AP$27=$H9)*(COLUMN('Next Steps'!$AE$8:$AP$27)-COLUMN('Next Steps'!$AE$6)+1)))) | H9: =IFERROR(SMALL('Next Steps'!$AE$8:$AP$27,1),"")
A10: =IF($H10="","",INT($H10)) | B10: =IF($A10="","",$A10-TODAY()) | C10: =IF($H10="","",INDEX('Next Steps'!$A$8:$A$27,SUMPRODUCT(('Next Steps'!$AE$8:$AP$27=$H10)*(ROW('Next Steps'!$AE$8:$AP$27)-7)))) | D10: =IF($H10="","",INDEX('Next Steps'!$AE$6:$AP$6,SUMPRODUCT(('Next Steps'!$AE$8:$AP$27=$H10)*(COLUMN('Next Steps'!$AE$8:$AP$27)-COLUMN('Next Steps'!$AE$6)+1)))) | H10: =IFERROR(SMALL('Next Steps'!$AE$8:$AP$27,2),"")
A11: =IF($H11="","",INT($H11)) | B11: =IF($A11="","",$A11-TODAY()) | C11: =IF($H11="","",INDEX('Next Steps'!$A$8:$A$27,SUMPRODUCT(('Next Steps'!$AE$8:$AP$27=$H11)*(ROW('Next Steps'!$AE$8:$AP$27)-7)))) | D11: =IF($H11="","",INDEX('Next Steps'!$AE$6:$AP$6,SUMPRODUCT(('Next Steps'!$AE$8:$AP$27=$H11)*(COLUMN('Next Steps'!$AE$8:$AP$27)-COLUMN('Next Steps'!$AE$6)+1)))) | H11: =IFERROR(SMALL('Next Steps'!$AE$8:$AP$27,3),"")
A12: =IF($H12="","",INT($H12)) | B12: =IF($A12="","",$A12-TODAY()) | C12: =IF($H12="","",INDEX('Next Steps'!$A$8:$A$27,SUMPRODUCT(('Next Steps'!$AE$8:$AP$27=$H12)*(ROW('Next Steps'!$AE$8:$AP$27)-7)))) | D12: =IF($H12="","",INDEX('Next Steps'!$AE$6:$AP$6,SUMPRODUCT(('Next Steps'!$AE$8:$AP$27=$H12)*(COLUMN('Next Steps'!$AE$8:$AP$27)-COLUMN('Next Steps'!$AE$6)+1)))) | H12: =IFERROR(SMALL('Next Steps'!$AE$8:$AP$27,4),"")
A13: =IF($H13="","",INT($H13)) | B13: =IF($A13="","",$A13-TODAY()) | C13: =IF($H13="","",INDEX('Next Steps'!$A$8:$A$27,SUMPRODUCT(('Next Steps'!$AE$8:$AP$27=$H13)*(ROW('Next Steps'!$AE$8:$AP$27)-7)))) | D13: =IF($H13="","",INDEX('Next Steps'!$AE$6:$AP$6,SUMPRODUCT(('Next Steps'!$AE$8:$AP$27=$H13)*(COLUMN('Next Steps'!$AE$8:$AP$27)-COLUMN('Next Steps'!$AE$6)+1)))) | H13: =IFERROR(SMALL('Next Steps'!$AE$8:$AP$27,5),"")
A14: =IF($H14="","",INT($H14)) | B14: =IF($A14="","",$A14-TODAY()) | C14: =IF($H14="","",INDEX('Next Steps'!$A$8:$A$27,SUMPRODUCT(('Next Steps'!$AE$8:$AP$27=$H14)*(ROW('Next Steps'!$AE$8:$AP$27)-7)))) | D14: =IF($H14="","",INDEX('Next Steps'!$AE$6:$AP$6,SUMPRODUCT(('Next Steps'!$AE$8:$AP$27=$H14)*(COLUMN('Next Steps'!$AE$8:$AP$27)-COLUMN('Next Steps'!$AE$6)+1)))) | H14: =IFERROR(SMALL('Next Steps'!$AE$8:$AP$27,6),"")
A15: =IF($H15="","",INT($H15)) | B15: =IF($A15="","",$A15-TODAY()) | C15: =IF($H15="","",INDEX('Next Steps'!$A$8:$A$27,SUMPRODUCT(('Next Steps'!$AE$8:$AP$27=$H15)*(ROW('Next Steps'!$AE$8:$AP$27)-7)))) | D15: =IF($H15="","",INDEX('Next Steps'!$AE$6:$AP$6,SUMPRODUCT(('Next Steps'!$AE$8:$AP$27=$H15)*(COLUMN('Next Steps'!$AE$8:$AP$27)-COLUMN('Next Steps'!$AE$6)+1)))) | H15: =IFERROR(SMALL('Next Steps'!$AE$8:$AP$27,7),"")
A16: =IF($H16="","",INT($H16)) | B16: =IF($A16="","",$A16-TODAY()) | C16: =IF($H16="","",INDEX('Next Steps'!$A$8:$A$27,SUMPRODUCT(('Next Steps'!$AE$8:$AP$27=$H16)*(ROW('Next Steps'!$AE$8:$AP$27)-7)))) | D16: =IF($H16="","",INDEX('Next Steps'!$AE$6:$AP$6,SUMPRODUCT(('Next Steps'!$AE$8:$AP$27=$H16)*(COLUMN('Next Steps'!$AE$8:$AP$27)-COLUMN('Next Steps'!$AE$6)+1)))) | H16: =IFERROR(SMALL('Next Steps'!$AE$8:$AP$27,8),"")
A17: =IF($H17="","",INT($H17)) | B17: =IF($A17="","",$A17-TODAY()) | C17: =IF($H17="","",INDEX('Next Steps'!$A$8:$A$27,SUMPRODUCT(('Next Steps'!$AE$8:$AP$27=$H17)*(ROW('Next Steps'!$AE$8:$AP$27)-7)))) | D17: =IF($H17="","",INDEX('Next Steps'!$AE$6:$AP$6,SUMPRODUCT(('Next Steps'!$AE$8:$AP$27=$H17)*(COLUMN('Next Steps'!$AE$8:$AP$27)-COLUMN('Next Steps'!$AE$6)+1)))) | H17: =IFERROR(SMALL('Next Steps'!$AE$8:$AP$27,9),"")
A18: =IF($H18="","",INT($H18)) | B18: =IF($A18="","",$A18-TODAY()) | C18: =IF($H18="","",INDEX('Next Steps'!$A$8:$A$27,SUMPRODUCT(('Next Steps'!$AE$8:$AP$27=$H18)*(ROW('Next Steps'!$AE$8:$AP$27)-7)))) | D18: =IF($H18="","",INDEX('Next Steps'!$AE$6:$AP$6,SUMPRODUCT(('Next Steps'!$AE$8:$AP$27=$H18)*(COLUMN('Next Steps'!$AE$8:$AP$27)-COLUMN('Next Steps'!$AE$6)+1)))) | H18: =IFERROR(SMALL('Next Steps'!$AE$8:$AP$27,10),"")
A19: Check these off on the Next Steps tab.
A21: Session | B21: Track | C21: Owner | D21: Deliverable | E21: Done | G21: Notes
A22: Getting started | due Thursday October 15
A23: 46310 | B23: Foundation | C23: Student | D23: Fill in the Me tab: GPA, SAT/ACT, accounts, recommenders | E23: =FALSE() -> FALSE
A24: 46310 | B24: Foundation | C24: Student | D24: Create Common App and GAfutures accounts | E24: =FALSE() -> FALSE
A25: 46310 | B25: Foundation | C25: Parent | D25: Create StudentAID.gov accounts (FSA ID): one for you, one for a parent | E25: =FALSE() -> FALSE
A26: 46310 | B26: Applications | C26: Student | D26: Explore: add 6 to 10 colleges to My Colleges (about 2 Likely, 3 to 4 Target, 2 Reach) and pick a round for each | E26: =FALSE() -> FALSE
A27: UB Session | Thursday October 8
A28: 46303 | B28: Applications | C28: Student | D28: Personal statement: topic locked and full Draft 1 (about 650 words) | E28: =FALSE() -> FALSE
A29: 46303 | B29: Applications | C29: Student | D29: Close the early list: every college due on or before November 1 confirmed in or out | E29: =FALSE() -> FALSE
A30: 46303 | B30: Applications | C30: Student | D30: Ask two teachers and your school counselor for recommendations. Give them your brag sheet and deadline list | E30: =FALSE() -> FALSE
A31: 46303 | B31: Foundation | C31: Parent | D31: Gather FAFSA documents: 2025 tax returns and W-2s | E31: =FALSE() -> FALSE
A32: Getting started | due Thursday October 15
A33: 46310 | B33: Applications | C33: Student | D33: UGA and Georgia Tech Early Action due today, if on your list | E33: =FALSE() -> FALSE
A34: 46310 | B34: Applications | C34: Student | D34: Personal statement Draft 2, near-final | E34: =FALSE() -> FALSE
A35: 46310 | B35: Foundation | C35: Parent | D35: Submit the 2027-28 FAFSA together (student and parent sections) | E35: =FALSE() -> FALSE
A36: 46310 | B36: Scholarships | C36: Student | D36: Add at least ten scholarships to Money, local ones first | E36: =FALSE() -> FALSE
A37: UB Session | Thursday October 22
A38: 46317 | B38: Applications | C38: Student | D38: Personal statement final | E38: =FALSE() -> FALSE
A39: 46317 | B39: Applications | C39: Student | D39: Extra essays done for every college due November 1 | E39: =FALSE() -> FALSE
A40: 46317 | B40: Foundation | C40: Student | D40: Georgia Match: log into GAfutures and claim your spot at up to three colleges | E40: =FALSE() -> FALSE
A41: 46317 | B41: Scholarships | C41: Student | D41: Two scholarship submissions | E41: =FALSE() -> FALSE
A42: UB Session | Thursday October 29
A43: 46324 | B43: Applications | C43: Student | D43: Submit every November 1 application. Confirm transcript and scores were sent | E43: =FALSE() -> FALSE
A44: 46324 | B44: Foundation | C44: Parent | D44: CSS Profile, only if a college on your list requires it | E44: =FALSE() -> FALSE
...

Sheet Explore
A1: Explore Colleges
A2: Every college in the UB database, labeled for you. Use the filter arrows on the header row to sort or narrow (for example Fit = Likely, or Category = HBCU). To add a college, pick it on My Colleges.
B4: Colleges in database | C4: Likely for me | D4: Target for me | E4: Reach for me | I4: Based on | X4: =IF(ISNUMBER(Me!$B$13),Me!$B$13,IF(ISNUMBER(Me!$B$14),30*Me!$B$14+490,"")) -> 850 | Y4: =IF(ISNUMBER(Me!$B$11),Me!$B$11,IF(ISNUMBER(Me!$B$10),Me!$B$10,"")) -> 3.5
B5: =COUNTIF(B8:B406,"?*") -> 205 | C5: =COUNTIF(E8:E406,"Likely") -> 22 | D5: =COUNTIF(E8:E406,"Target") -> 48 | E5: =COUNTIF(E8:E406,"Reach") -> 106 | I5: =IF(AND(NOT(ISNUMBER($X$4)),NOT(ISNUMBER($Y$4))),"Add your GPA and SAT/ACT on Me",IF(ISNUMBER(Me!$B$13),"SAT "&Me!$B$13,IF(ISNUMBER(Me!$B$14),"ACT "&Me!$B$14,"no test"))&" and GPA "&IF(ISNUMBER($Y$4),$Y$4,"missing")) -> SAT 850 and GPA 3.5
B6: Labels are estimates. Each college is judged on both your test score and your GPA, and the weaker of the two counts. Colleges admitting under 15% are always Reach.
A7: On My List | B7: College | C7: Category | D7: Location | E7: Fit for Me | F7: Admit Rate | G7: SAT Middle 50% | H7: Avg HS GPA | I7: Earliest Deadline | J7: Earliest Round | K7: Regular Deadline | L7: How to Apply | M7: App Fee | N7: Test Policy | O7: Extra Essays | P7: CSS Profile | Q7: Net Price (income under $30k) | R7: 6-Yr Grad Rate | S7: Data Status | T7: Admissions Page | U7: sat score | V7: gpa score | W7: combined
A8: =IF(B8="","",IF(COUNTIF('My Colleges'!$B$8:$B$27,B8)>0,"On list","")) | B8: =IF(DB_Colleges!A2="","",DB_Colleges!A2) -> University of Georgia | C8: =IF(B8="","",DB_Colleges!B2) -> Georgia Public (USG) | D8: =IF(B8="","",DB_Colleges!C2&", "&DB_Colleges!D2) -> Athens, GA | E8: =IF(B8="","",IF(AND(NOT(ISNUMBER($X$4)),NOT(ISNUMBER($Y$4))),"Add scores",IF(NOT(ISNUMBER(DB_Colleges!Y2)),IF(OR(C8="Ivy League",C8="Highly Selective"),"Reach",IF(COUNT(U8:V8)=0,"No data",CHOOSE(W8+2,"Reach","Target","Likely"))),IF(DB_Colleges!Y2<0.15,"Reach",IF(DB_Colleges!Y2>=0.75,IF(W8>=0,"Likely","Target"),IF(DB_Colleges!Y2>=0.4,CHOOSE(W8+2,"Reach","Target","Likely"),IF(W8=1,"Target","Reach"))))))) -> Reach | F8: =IF(OR(B8="",NOT(ISNUMBER(DB_Colleges!Y2))),"",DB_Colleges!Y2) -> 0.3 | G8: =IF(OR(B8="",NOT(ISNUMBER(DB_Colleges!Z2))),"",DB_Colleges!Z2&"-"&DB_Colleges!AA2) -> 1360-1500 | H8: =IF(OR(B8="",NOT(ISNUMBER(DB_Colleges!AD2))),"",DB_Colleges!AD2) -> 4.27 | I8: =IF(B8="","",IF(COUNT(DB_Colleges!I2:O2)=0,IF(DB_Colleges!P2="Yes","Rolling","Check site"),MIN(DB_Colleges!I2:O2))) -> 46310 | J8: =IF(OR(B8="",COUNT(DB_Colleges!I2:O2)=0),"",INDEX({"ED","ED II","EA","EA II","REA","RD","Priority"},MATCH(MIN(DB_Colleges!I2:O2),DB_Colleges!I2:O2,0))) -> EA | K8: =IF(OR(B8="",NOT(ISNUMBER(DB_Colleges!N2))),"",DB_Colleges!N2) -> 46388 | L8: =IF(B8="","",DB_Colleges!G2&"") -> Common App | M8: =IF(OR(B8="",NOT(ISNUMBER(DB_Colleges!S2))),"",DB_Colleges!S2) -> 70 | N8: =IF(B8="","",DB_Colleges!U2&"") -> Required | O8: =IF(B8="","",IF(ISNUMBER(DB_Colleges!AH2),DB_Colleges!AH2,"Check")) -> 0 | P8: =IF(B8="","",DB_Colleges!W2&"") -> Not required | Q8: =IF(OR(B8="",NOT(ISNUMBER(DB_Colleges!AF2))),"",DB_Colleges!AF2) | R8: =IF(OR(B8="",NOT(ISNUMBER(DB_Colleges!AG2))),"",DB_Colleges!AG2) -> 0.9 | S8: =IF(B8="","",DB_Colleges!AK2&"") -> Official 2026-27 | T8: =IF(B8="","",DB_Colleges!AI2&"") -> https://admissions.uga.edu/apply/first-year-applicants/ | U8: =IF(AND(ISNUMBER($X$4),ISNUMBER(DB_Colleges!Z2),ISNUMBER(DB_Colleges!AA2)),IF($X$4>=DB_Colleges!AA2,1,IF($X$4<DB_Colleges!Z2,-1,0)),"") -> -1 | V8: =IF(AND(ISNUMBER($Y$4),ISNUMBER(DB_Colleges!AD2)),IF($Y$4>=DB_Colleges!AD2+0.15,1,IF($Y$4<DB_Colleges!AD2-0.2,-1,0)),"") -> -1 | W8: =IF(COUNT(U8:V8)=0,0,MIN(U8:V8)) -> -1
A9: =IF(B9="","",IF(COUNTIF('My Colleges'!$B$8:$B$27,B9)>0,"On list","")) | B9: =IF(DB_Colleges!A3="","",DB_Colleges!A3) -> Georgia Institute of Technology | C9: =IF(B9="","",DB_Colleges!B3) -> Georgia Public (USG) | D9: =IF(B9="","",DB_Colleges!C3&", "&DB_Colleges!D3) -> Atlanta, GA | E9: =IF(B9="","",IF(AND(NOT(ISNUMBER($X$4)),NOT(ISNUMBER($Y$4))),"Add scores",IF(NOT(ISNUMBER(DB_Colleges!Y3)),IF(OR(C9="Ivy League",C9="Highly Selective"),"Reach",IF(COUNT(U9:V9)=0,"No data",CHOOSE(W9+2,"Reach","Target","Likely"))),IF(DB_Colleges!Y3<0.15,"Reach",IF(DB_Colleges!Y3>=0.75,IF(W9>=0,"Likely","Target"),IF(DB_Colleges!Y3>=0.4,CHOOSE(W9+2,"Reach","Target","Likely"),IF(W9=1,"Target","Reach"))))))) -> Reach | F9: =IF(OR(B9="",NOT(ISNUMBER(DB_Colleges!Y3))),"",DB_Colleges!Y3) -> 0.133 | G9: =IF(OR(B9="",NOT(ISNUMBER(DB_Colleges!Z3))),"",DB_Colleges!Z3&"-"&DB_Colleges!AA3) -> 1370-1530 | H9: =IF(OR(B9="",NOT(ISNUMBER(DB_Colleges!AD3))),"",DB_Colleges!AD3) -> 4.17 | I9: =IF(B9="","",IF(COUNT(DB_Colleges!I3:O3)=0,IF(DB_Colleges!P3="Yes","Rolling","Check site"),MIN(DB_Colleges!I3:O3))) -> 46310 | J9: =IF(OR(B9="",COUNT(DB_Colleges!I3:O3)=0),"",INDEX({"ED","ED II","EA","EA II","REA","RD","Priority"},MATCH(MIN(DB_Colleges!I3:O3),DB_Colleges!I3:O3,0))) -> EA | K9: =IF(OR(B9="",NOT(ISNUMBER(DB_Colleges!N3))),"",DB_Colleges!N3) -> 46393 | L9: =IF(B9="","",DB_Colleges!G3&"") -> Common App | M9: =IF(OR(B9="",NOT(ISNUMBER(DB_Colleges!S3))),"",DB_Colleges!S3) -> 75 | N9: =IF(B9="","",DB_Colleges!U3&"") -> Required | O9: =IF(B9="","",IF(ISNUMBER(DB_Colleges!AH3),DB_Colleges!AH3,"Check")) -> Check | P9: =IF(B9="","",DB_Colleges!W3&"") -> Not required | Q9: =IF(OR(B9="",NOT(ISNUMBER(DB_Colleges!AF3))),"",DB_Colleges!AF3) | R9: =IF(OR(B9="",NOT(ISNUMBER(DB_Colleges!AG3))),"",DB_Colleges!AG3) -> 0.94 | S9: =IF(B9="","",DB_Colleges!AK3&"") -> Mixed | T9: =IF(B9="","",DB_Colleges!AI3&"") -> https://admission.gatech.edu/first-year/ | U9: =IF(AND(ISNUMBER($X$4),ISNUMBER(DB_Colleges!Z3),ISNUMBER(DB_Colleges!AA3)),IF($X$4>=DB_Colleges!AA3,1,IF($X$4<DB_Colleges!Z3,-1,0)),"") -> -1 | V9: =IF(AND(ISNUMBER($Y$4),ISNUMBER(DB_Colleges!AD3)),IF($Y$4>=DB_Colleges!AD3+0.15,1,IF($Y$4<DB_Colleges!AD3-0.2,-1,0)),"") -> -1 | W9: =IF(COUNT(U9:V9)=0,0,MIN(U9:V9)) -> -1
A10: =IF(B10="","",IF(COUNTIF('My Colleges'!$B$8:$B$27,B10)>0,"On list","")) | B10: =IF(DB_Colleges!A4="","",DB_Colleges!A4) -> Georgia State University | C10: =IF(B10="","",DB_Colleges!B4) -> Georgia Public (USG) | D10: =IF(B10="","",DB_Colleges!C4&", "&DB_Colleges!D4) -> Atlanta, GA | E10: =IF(B10="","",IF(AND(NOT(ISNUMBER($X$4)),NOT(ISNUMBER($Y$4))),"Add scores",IF(NOT(ISNUMBER(DB_Colleges!Y4)),IF(OR(C10="Ivy League",C10="Highly Selective"),"Reach",IF(COUNT(U10:V10)=0,"No data",CHOOSE(W10+2,"Reach","Target","Likely"))),IF(DB_Colleges!Y4<0.15,"Reach",IF(DB_Colleges!Y4>=0.75,IF(W10>=0,"Likely","Target"),IF(DB_Colleges!Y4>=0.4,CHOOSE(W10+2,"Reach","Target","Likely"),IF(W10=1,"Target","Reach"))))))) -> Target | F10: =IF(OR(B10="",NOT(ISNUMBER(DB_Colleges!Y4))),"",DB_Colleges!Y4) -> 0.57 | G10: =IF(OR(B10="",NOT(ISNUMBER(DB_Colleges!Z4))),"",DB_Colleges!Z4&"-"&DB_Colleges!AA4) | H10: =IF(OR(B10="",NOT(ISNUMBER(DB_Colleges!AD4))),"",DB_Colleges!AD4) | I10: =IF(B10="","",IF(COUNT(DB_Colleges!I4:O4)=0,IF(DB_Colleges!P4="Yes","Rolling","Check site"),MIN(DB_Colleges!I4:O4))) -> 46341 | J10: =IF(OR(B10="",COUNT(DB_Colleges!I4:O4)=0),"",INDEX({"ED","ED II","EA","EA II","REA","RD","Priority"},MATCH(MIN(DB_Colleges!I4:O4),DB_Colleges!I4:O4,0))) -> EA | K10: =IF(OR(B10="",NOT(ISNUMBER(DB_Colleges!N4))),"",DB_Colleges!N4) -> 46508 | L10: =IF(B10="","",DB_Colleges!G4&"") -> Common App | M10: =IF(OR(B10="",NOT(ISNUMBER(DB_Colleges!S4))),"",DB_Colleges!S4) -> 60 | N10: =IF(B10="","",DB_Colleges!U4&"") -> Required | O10: =IF(B10="","",IF(ISNUMBER(DB_Colleges!AH4),DB_Colleges!AH4,"Check")) -> Check | P10: =IF(B10="","",DB_Colleges!W4&"") -> Not required | Q10: =IF(OR(B10="",NOT(ISNUMBER(DB_Colleges!AF4))),"",DB_Colleges!AF4) | R10: =IF(OR(B10="",NOT(ISNUMBER(DB_Colleges!AG4))),"",DB_Colleges!AG4) | S10: =IF(B10="","",DB_Colleges!AK4&"") -> Mixed | T10: =IF(B10="","",DB_Colleges!AI4&"") -> https://admissions.gsu.edu/bachelors-degree/apply/ | U10: =IF(AND(ISNUMBER($X$4),ISNUMBER(DB_Colleges!Z4),ISNUMBER(DB_Colleges!AA4)),IF($X$4>=DB_Colleges!AA4,1,IF($X$4<DB_Colleges!Z4,-1,0)),"") | V10: =IF(AND(ISNUMBER($Y$4),ISNUMBER(DB_Colleges!AD4)),IF($Y$4>=DB_Colleges!AD4+0.15,1,IF($Y$4<DB_Colleges!AD4-0.2,-1,0)),"") | W10: =IF(COUNT(U10:V10)=0,0,MIN(U10:V10)) -> 0
A11: =IF(B11="","",IF(COUNTIF('My Colleges'!$B$8:$B$27,B11)>0,"On list","")) | B11: =IF(DB_Colleges!A5="","",DB_Colleges!A5) -> Kennesaw State University | C11: =IF(B11="","",DB_Colleges!B5) -> Georgia Public (USG) | D11: =IF(B11="","",DB_Colleges!C5&", "&DB_Colleges!D5) -> Kennesaw, GA | E11: =IF(B11="","",IF(AND(NOT(ISNUMBER($X$4)),NOT(ISNUMBER($Y$4))),"Add scores",IF(NOT(ISNUMBER(DB_Colleges!Y5)),IF(OR(C11="Ivy League",C11="Highly Selective"),"Reach",IF(COUNT(U11:V11)=0,"No data",CHOOSE(W11+2,"Reach","Target","Likely"))),IF(DB_Colleges!Y5<0.15,"Reach",IF(DB_Colleges!Y5>=0.75,IF(W11>=0,"Likely","Target"),IF(DB_Colleges!Y5>=0.4,CHOOSE(W11+2,"Reach","Target","Likely"),IF(W11=1,"Target","Reach"))))))) -> Target | F11: =IF(OR(B11="",NOT(ISNUMBER(DB_Colleges!Y5))),"",DB_Colleges!Y5) -> 0.79 | G11: =IF(OR(B11="",NOT(ISNUMBER(DB_Colleges!Z5))),"",DB_Colleges!Z5&"-"&DB_Colleges!AA5) -> 990-1230 | H11: =IF(OR(B11="",NOT(ISNUMBER(DB_Colleges!AD5))),"",DB_Colleges!AD5) -> 3.5 | I11: =IF(B11="","",IF(COUNT(DB_Colleges!I5:O5)=0,IF(DB_Colleges!P5="Yes","Rolling","Check site"),MIN(DB_Colleges!I5:O5))) -> 46328 | J11: =IF(OR(B11="",COUNT(DB_Colleges!I5:O5)=0),"",INDEX({"ED","ED II","EA","EA II","REA","RD","Priority"},MATCH(MIN(DB_Colleges!I5:O5),DB_Colleges!I5:O5,0))) -> Priority | K11: =IF(OR(B11="",NOT(ISNUMBER(DB_Colleges!N5))),"",DB_Colleges!N5) -> 46569 | L11: =IF(B11="","",DB_Colleges!G5&"") -> Common App; School portal | M11: =IF(OR(B11="",NOT(ISNUMBER(DB_Colleges!S5))),"",DB_Colleges!S5) -> 40 | N11: =IF(B11="","",DB_Colleges!U5&"") -> Required | O11: =IF(B11="","",IF(ISNUMBER(DB_Colleges!AH5),DB_Colleges!AH5,"Check")) -> Check | P11: =IF(B11="","",DB_Colleges!W5&"") -> Not required | Q11: =IF(OR(B11="",NOT(ISNUMBER(DB_Colleges!AF5))),"",DB_Colleges!AF5) | R11: =IF(OR(B11="",NOT(ISNUMBER(DB_Colleges!AG5))),"",DB_Colleges!AG5) | S11: =IF(B11="","",DB_Colleges!AK5&"") -> Mixed | T11: =IF(B11="","",DB_Colleges!AI5&"") -> https://www.kennesaw.edu/admissions/undergraduate/admission-requirements/freshman.php | U11: =IF(AND(ISNUMBER($X$4),ISNUMBER(DB_Colleges!Z5),ISNUMBER(DB_Colleges!AA5)),IF($X$4>=DB_Colleges!AA5,1,IF($X$4<DB_Colleges!Z5,-1,0)),"") -> -1 | V11: =IF(AND(ISNUMBER($Y$4),ISNUMBER(DB_Colleges!AD5)),IF($Y$4>=DB_Colleges!AD5+0.15,1,IF($Y$4<DB_Colleges!AD5-0.2,-1,0)),"") -> 0 | W11: =IF(COUNT(U11:V11)=0,0,MIN(U11:V11)) -> -1
A12: =IF(B12="","",IF(COUNTIF('My Colleges'!$B$8:$B$27,B12)>0,"On list","")) | B12: =IF(DB_Colleges!A6="","",DB_Colleges!A6) -> Georgia Southern University | C12: =IF(B12="","",DB_Colleges!B6) -> Georgia Public (USG) | D12: =IF(B12="","",DB_Colleges!C6&", "&DB_Colleges!D6) -> Statesboro, GA | E12: =IF(B12="","",IF(AND(NOT(ISNUMBER($X$4)),NOT(ISNUMBER($Y$4))),"Add scores",IF(NOT(ISNUMBER(DB_Colleges!Y6)),IF(OR(C12="Ivy League",C12="Highly Selective"),"Reach",IF(COUNT(U12:V12)=0,"No data",CHOOSE(W12+2,"Reach","Target","Likely"))),IF(DB_Colleges!Y6<0.15,"Reach",IF(DB_Colleges!Y6>=0.75,IF(W12>=0,"Likely","Target"),IF(DB_Colleges!Y6>=0.4,CHOOSE(W12+2,"Reach","Target","Likely"),IF(W12=1,"Target","Reach"))))))) -> Reach | F12: =IF(OR(B12="",NOT(ISNUMBER(DB_Colleges!Y6))),"",DB_Colleges!Y6) -> 0.7 | G12: =IF(OR(B12="",NOT(ISNUMBER(DB_Colleges!Z6))),"",DB_Colleges!Z6&"-"&DB_Colleges!AA6) -> 940-1130 | H12: =IF(OR(B12="",NOT(ISNUMBER(DB_Colleges!AD6))),"",DB_Colleges!AD6) | I12: =IF(B12="","",IF(COUNT(DB_Colleges!I6:O6)=0,IF(DB_Colleges!P6="Yes","Rolling","Check site"),MIN(DB_Colleges!I6:O6))) -> 46600 | J12: =IF(OR(B12="",COUNT(DB_Colleges!I6:O6)=0),"",INDEX({"ED","ED II","EA","EA II","REA","RD","Priority"},MATCH(MIN(DB_Colleges!I6:O6),DB_Colleges!I6:O6,0))) -> RD | K12: =IF(OR(B12="",NOT(ISNUMBER(DB_Colleges!N6))),"",DB_Colleges!N6) -> 46600 | L12: =IF(B12="","",DB_Colleges!G6&"") -> Common App; School portal | M12: =IF(OR(B12="",NOT(ISNUMBER(DB_Colleges!S6))),"",DB_Colleges!S6) -> 30 | N12: =IF(B12="","",DB_Colleges!U6&"") -> Required | O12: =IF(B12="","",IF(ISNUMBER(DB_Colleges!AH6),DB_Colleges!AH6,"Check")) -> Check | P12: =IF(B12="","",DB_Colleges!W6&"") -> Not required | Q12: =IF(OR(B12="",NOT(ISNUMBER(DB_Colleges!AF6))),"",DB_Colleges!AF6) | R12: =IF(OR(B12="",NOT(ISNUMBER(DB_Colleges!AG6))),"",DB_Colleges!AG6) | S12: =IF(B12="","",DB_Colleges!AK6&"") -> Mixed | T12: =IF(B12="","",DB_Colleges!AI6&"") -> https://www.georgiasouthern.edu/admissions-aid/first-year-students | U12: =IF(AND(ISNUMBER($X$4),ISNUMBER(DB_Colleges!Z6),ISNUMBER(DB_Colleges!AA6)),IF($X$4>=DB_Colleges!AA6,1,IF($X$4<DB_Colleges!Z6,-1,0)),"") -> -1 | V12: =IF(AND(ISNUMBER($Y$4),ISNUMBER(DB_Colleges!AD6)),IF($Y$4>=DB_Colleges!AD6+0.15,1,IF($Y$4<DB_Colleges!AD6-0.2,-1,0)),"") | W12: =IF(COUNT(U12:V12)=0,0,MIN(U12:V12)) -> -1
A13: =IF(B13="","",IF(COUNTIF('My Colleges'!$B$8:$B$27,B13)>0,"On list","")) | B13: =IF(DB_Colleges!A7="","",DB_Colleges!A7) -> Augusta University | C13: =IF(B13="","",DB_Colleges!B7) -> Georgia Public (USG) | D13: =IF(B13="","",DB_Colleges!C7&", "&DB_Colleges!D7) -> Augusta, GA | E13: =IF(B13="","",IF(AND(NOT(ISNUMBER($X$4)),NOT(ISNUMBER($Y$4))),"Add scores",IF(NOT(ISNUMBER(DB_Colleges!Y7)),IF(OR(C13="Ivy League",C13="Highly Selective"),"Reach",IF(COUNT(U13:V13)=0,"No data",CHOOSE(W13+2,"Reach","Target","Likely"))),IF(DB_Colleges!Y7<0.15,"Reach",IF(DB_Colleges!Y7>=0.75,IF(W13>=0,"Likely","Target"),IF(DB_Colleges!Y7>=0.4,CHOOSE(W13+2,"Reach","Target","Likely"),IF(W13=1,"Target","Reach"))))))) -> Reach | F13: =IF(OR(B13="",NOT(ISNUMBER(DB_Colleges!Y7))),"",DB_Colleges!Y7) | G13: =IF(OR(B13="",NOT(ISNUMBER(DB_Colleges!Z7))),"",DB_Colleges!Z7&"-"&DB_Colleges!AA7) -> 970-1140 | H13: =IF(OR(B13="",NOT(ISNUMBER(DB_Colleges!AD7))),"",DB_Colleges!AD7) | I13: =IF(B13="","",IF(COUNT(DB_Colleges!I7:O7)=0,IF(DB_Colleges!P7="Yes","Rolling","Check site"),MIN(DB_Colleges!I7:O7))) -> 46326 | J13: =IF(OR(B13="",COUNT(DB_Colleges!I7:O7)=0),"",INDEX({"ED","ED II","EA","EA II","REA","RD","Priority"},MATCH(MIN(DB_Colleges!I7:O7),DB_Colleges!I7:O7,0))) -> EA | K13: =IF(OR(B13="",NOT(ISNUMBER(DB_Colleges!N7))),"",DB_Colleges!N7) -> 46569 | L13: =IF(B13="","",DB_Colleges!G7&"") -> Common App | M13: =IF(OR(B13="",NOT(ISNUMBER(DB_Colleges!S7))),"",DB_Colleges!S7) -> 60 | N13: =IF(B13="","",DB_Colleges!U7&"") -> Required | O13: =IF(B13="","",IF(ISNUMBER(DB_Colleges!AH7),DB_Colleges!AH7,"Check")) -> Check | P13: =IF(B13="","",DB_Colleges!W7&"") -> Not required | Q13: =IF(OR(B13="",NOT(ISNUMBER(DB_Colleges!AF7))),"",DB_Colleges!AF7) | R13: =IF(OR(B13="",NOT(ISNUMBER(DB_Colleges!AG7))),"",DB_Colleges!AG7) | S13: =IF(B13="","",DB_Colleges!AK7&"") -> Mixed | T13: =IF(B13="","",DB_Colleges!AI7&"") -> https://www.augusta.edu/admissions/freshman.php | U13: =IF(AND(ISNUMBER($X$4),ISNUMBER(DB_Colleges!Z7),ISNUMBER(DB_Colleges!AA7)),IF($X$4>=DB_Colleges!AA7,1,IF($X$4<DB_Colleges!Z7,-1,0)),"") -> -1 | V13: =IF(AND(ISNUMBER($Y$4),ISNUMBER(DB_Colleges!AD7)),IF($Y$4>=DB_Colleges!AD7+0.15,1,IF($Y$4<DB_Colleges!AD7-0.2,-1,0)),"") | W13: =IF(COUNT(U13:V13)=0,0,MIN(U13:V13)) -> -1
A14: =IF(B14="","",IF(COUNTIF('My Colleges'!$B$8:$B$27,B14)>0,"On list","")) | B14: =IF(DB_Colleges!A8="","",DB_Colleges!A8) -> Valdosta State University | C14: =IF(B14="","",DB_Colleges!B8) -> Georgia Public (USG) | D14: =IF(B14="","",DB_Colleges!C8&", "&DB_Colleges!D8) -> Valdosta, GA | E14: =IF(B14="","",IF(AND(NOT(ISNUMBER($X$4)),NOT(ISNUMBER($Y$4))),"Add scores",IF(NOT(ISNUMBER(DB_Colleges!Y8)),IF(OR(C14="Ivy League",C14="Highly Selective"),"Reach",IF(COUNT(U14:V14)=0,"No data",CHOOSE(W14+2,"Reach","Target","Likely"))),IF(DB_Colleges!Y8<0.15,"Reach",IF(DB_Colleges!Y8>=0.75,IF(W14>=0,"Likely","Target"),IF(DB_Colleges!Y8>=0.4,CHOOSE(W14+2,"Reach","Target","Likely"),IF(W14=1,"Target","Reach"))))))) -> Target | F14: =IF(OR(B14="",NOT(ISNUMBER(DB_Colleges!Y8))),"",DB_Colleges!Y8) -> 0.78 | G14: =IF(OR(B14="",NOT(ISNUMBER(DB_Colleges!Z8))),"",DB_Colleges!Z8&"-"&DB_Colleges!AA8) -> 920-1110 | H14: =IF(OR(B14="",NOT(ISNUMBER(DB_Colleges!AD8))),"",DB_Colleges!AD8) | I14: =IF(B14="","",IF(COUNT(DB_Colleges!I8:O8)=0,IF(DB_Colleges!P8="Yes","Rolling","Check site"),MIN(DB_Colleges!I8:O8))) -> Rolling | J14: =IF(OR(B14="",COUNT(DB_Colleges!I8:O8)=0),"",INDEX({"ED","ED II","EA","EA II","REA","RD","Priority"},MATCH(MIN(DB_Colleges!I8:O8),DB_Colleges!I8:O8,0))) | K14: =IF(OR(B14="",NOT(ISNUMBER(DB_Colleges!N8))),"",DB_Colleges!N8) | L14: =IF(B14="","",DB_Colleges!G8&"") -> School portal | M14: =IF(OR(B14="",NOT(ISNUMBER(DB_Colleges!S8))),"",DB_Colleges!S8) | N14: =IF(B14="","",DB_Colleges!U8&"") -> Optional | O14: =IF(B14="","",IF(ISNUMBER(DB_Colleges!AH8),DB_Colleges!AH8,"Check")) -> Check | P14: =IF(B14="","",DB_Colleges!W8&"") -> Not required | Q14: =IF(OR(B14="",NOT(ISNUMBER(DB_Colleges!AF8))),"",DB_Colleges!AF8) | R14: =IF(OR(B14="",NOT(ISNUMBER(DB_Colleges!AG8))),"",DB_Colleges!AG8) | S14: =IF(B14="","",DB_Colleges!AK8&"") -> Mixed | T14: =IF(B14="","",DB_Colleges!AI8&"") -> https://www.valdosta.edu/admissions/undergraduate/dates-and-events.php | U14: =IF(AND(ISNUMBER($X$4),ISNUMBER(DB_Colleges!Z8),ISNUMBER(DB_Colleges!AA8)),IF($X$4>=DB_Colleges!AA8,1,IF($X$4<DB_Colleges!Z8,-1,0)),"") -> -1 | V14: =IF(AND(ISNUMBER($Y$4),ISNUMBER(DB_Colleges!AD8)),IF($Y$4>=DB_Colleges!AD8+0.15,1,IF($Y$4<DB_Colleges!AD8-0.2,-1,0)),"") | W14: =IF(COUNT(U14:V14)=0,0,MIN(U14:V14)) -> -1
A15: =IF(B15="","",IF(COUNTIF('My Colleges'!$B$8:$B$27,B15)>0,"On list","")) | B15: =IF(DB_Colleges!A9="","",DB_Colleges!A9) -> University of West Georgia | C15: =IF(B15="","",DB_Colleges!B9) -> Georgia Public (USG) | D15: =IF(B15="","",DB_Colleges!C9&", "&DB_Colleges!D9) -> Carrollton, GA | E15: =IF(B15="","",IF(AND(NOT(ISNUMBER($X$4)),NOT(ISNUMBER($Y$4))),"Add scores",IF(NOT(ISNUMBER(DB_Colleges!Y9)),IF(OR(C15="Ivy League",C15="Highly Selective"),"Reach",IF(COUNT(U15:V15)=0,"No data",CHOOSE(W15+2,"Reach","Target","Likely"))),IF(DB_Colleges!Y9<0.15,"Reach",IF(DB_Colleges!Y9>=0.75,IF(W15>=0,"Likely","Target"),IF(DB_Colleges!Y9>=0.4,CHOOSE(W15+2,"Reach","Target","Likely"),IF(W15=1,"Target","Reach"))))))) -> Target | F15: =IF(OR(B15="",NOT(ISNUMBER(DB_Colleges!Y9))),"",DB_Colleges!Y9) -> 0.8 | G15: =IF(OR(B15="",NOT(ISNUMBER(DB_Colleges!Z9))),"",DB_Colleges!Z9&"-"&DB_Colleges!AA9) -> 930-1150 | H15: =IF(OR(B15="",NOT(ISNUMBER(DB_Colleges!AD9))),"",DB_Colleges!AD9) | I15: =IF(B15="","",IF(COUNT(DB_Colleges!I9:O9)=0,IF(DB_Colleges!P9="Yes","Rolling","Check site"),MIN(DB_Colleges!I9:O9))) -> 46326 | J15: =IF(OR(B15="",COUNT(DB_Colleges!I9:O9)=0),"",INDEX({"ED","ED II","EA","EA II","REA","RD","Priority"},MATCH(MIN(DB_Colleges!I9:O9),DB_Colleges!I9:O9,0))) -> EA | K15: =IF(OR(B15="",NOT(ISNUMBER(DB_Colleges!N9))),"",DB_Colleges!N9) -> 46607 | L15: =IF(B15="","",DB_Colleges!G9&"") -> School portal | M15: =IF(OR(B15="",NOT(ISNUMBER(DB_Colleges!S9))),"",DB_Colleges!S9) -> 40 | N15: =IF(B15="","",DB_Colleges!U9&"") -> Flexible | O15: =IF(B15="","",IF(ISNUMBER(DB_Colleges!AH9),DB_Colleges!AH9,"Check")) -> Check | P15: =IF(B15="","",DB_Colleges!W9&"") -> Not required | Q15: =IF(OR(B15="",NOT(ISNUMBER(DB_Colleges!AF9))),"",DB_Colleges!AF9) | R15: =IF(OR(B15="",NOT(ISNUMBER(DB_Colleges!AG9))),"",DB_Colleges!AG9) | S15: =IF(B15="","",DB_Colleges!AK9&"") -> Mixed | T15: =IF(B15="","",DB_Colleges!AI9&"") -> https://www.westga.edu/undergraduate-admissions/dates-deadlines.php | U15: =IF(AND(ISNUMBER($X$4),ISNUMBER(DB_Colleges!Z9),ISNUMBER(DB_Colleges!AA9)),IF($X$4>=DB_Colleges!AA9,1,IF($X$4<DB_Colleges!Z9,-1,0)),"") -> -1 | V15: =IF(AND(ISNUMBER($Y$4),ISNUMBER(DB_Colleges!AD9)),IF($Y$4>=DB_Colleges!AD9+0.15,1,IF($Y$4<DB_Colleges!AD9-0.2,-1,0)),"") | W15: =IF(COUNT(U15:V15)=0,0,MIN(U15:V15)) -> -1
A16: =IF(B16="","",IF(COUNTIF('My Colleges'!$B$8:$B$27,B16)>0,"On list","")) | B16: =IF(DB_Colleges!A10="","",DB_Colleges!A10) -> Georgia College & State University | C16: =IF(B16="","",DB_Colleges!B10) -> Georgia Public (USG) | D16: =IF(B16="","",DB_Colleges!C10&", "&DB_Colleges!D10) -> Milledgeville, GA | E16: =IF(B16="","",IF(AND(NOT(ISNUMBER($X$4)),NOT(ISNUMBER($Y$4))),"Add scores",IF(NOT(ISNUMBER(DB_Colleges!Y10)),IF(OR(C16="Ivy League",C16="Highly Selective"),"Reach",IF(COUNT(U16:V16)=0,"No data",CHOOSE(W16+2,"Reach","Target","Likely"))),IF(DB_Colleges!Y10<0.15,"Reach",IF(DB_Colleges!Y10>=0.75,IF(W16>=0,"Likely","Target"),IF(DB_Colleges!Y10>=0.4,CHOOSE(W16+2,"Reach","Target","Likely"),IF(W16=1,"Target","Reach"))))))) -> Target | F16: =IF(OR(B16="",NOT(ISNUMBER(DB_Colleges!Y10))),"",DB_Colleges!Y10) -> 0.85 | G16: =IF(OR(B16="",NOT(ISNUMBER(DB_Colleges!Z10))),"",DB_Colleges!Z10&"-"&DB_Colleges!AA10) -> 1110-1270 | H16: =IF(OR(B16="",NOT(ISNUMBER(DB_Colleges!AD10))),"",DB_Colleges!AD10) | I16: =IF(B16="","",IF(COUNT(DB_Colleges!I10:O10)=0,IF(DB_Colleges!P10="Yes","Rolling","Check site"),MIN(DB_Colleges!I10:O10))) -> 46310 | J16: =IF(OR(B16="",COUNT(DB_Colleges!I10:O10)=0),"",INDEX({"ED","ED II","EA","EA II","REA","RD","Priority"},MATCH(MIN(DB_Colleges!I10:O10),DB_Colleges!I10:O10,0))) -> EA | K16: =IF(OR(B16="",NOT(ISNUMBER(DB_Colleges!N10))),"",DB_Colleges!N10) | L16: =IF(B16="","",DB_Colleges!G10&"") -> Common App | M16: =IF(OR(B16="",NOT(ISNUMBER(DB_Colleges!S10))),"",DB_Colleges!S10) -> 50 | N16: =IF(B16="","",DB_Colleges!U10&"") -> Required | O16: =IF(B16="","",IF(ISNUMBER(DB_Colleges!AH10),DB_Colleges!AH10,"Check")) -> Check | P16: =IF(B16="","",DB_Colleges!W10&"") -> Not required | Q16: =IF(OR(B16="",NOT(ISNUMBER(DB_Colleges!AF10))),"",DB_Colleges!AF10) | R16: =IF(OR(B16="",NOT(ISNUMBER(DB_Colleges!AG10))),"",DB_Colleges!AG10) | S16: =IF(B16="","",DB_Colleges!AK10&"") -> Mixed | T16: =IF(B16="","",DB_Colleges!AI10&"") -> https://www.gcsu.edu/admissions/first-year | U16: =IF(AND(ISNUMBER($X$4),ISNUMBER(DB_Colleges!Z10),ISNUMBER(DB_Colleges!AA10)),IF($X$4>=DB_Colleges!AA10,1,IF($X$4<DB_Colleges!Z10,-1,0)),"") -> -1 | V16: =IF(AND(ISNUMBER($Y$4),ISNUMBER(DB_Colleges!AD10)),IF($Y$4>=DB_Colleges!AD10+0.15,1,IF($Y$4<DB_Colleges!AD10-0.2,-1,0)),"") | W16: =IF(COUNT(U16:V16)=0,0,MIN(U16:V16)) -> -1
A17: =IF(B17="","",IF(COUNTIF('My Colleges'!$B$8:$B$27,B17)>0,"On list","")) | B17: =IF(DB_Colleges!A11="","",DB_Colleges!A11) -> Columbus State University | C17: =IF(B17="","",DB_Colleges!B11) -> Georgia Public (USG) | D17: =IF(B17="","",DB_Colleges!C11&", "&DB_Colleges!D11) -> Columbus, GA | E17: =IF(B17="","",IF(AND(NOT(ISNUMBER($X$4)),NOT(ISNUMBER($Y$4))),"Add scores",IF(NOT(ISNUMBER(DB_Colleges!Y11)),IF(OR(C17="Ivy League",C17="Highly Selective"),"Reach",IF(COUNT(U17:V17)=0,"No data",CHOOSE(W17+2,"Reach","Target","Likely"))),IF(DB_Colleges!Y11<0.15,"Reach",IF(DB_Colleges!Y11>=0.75,IF(W17>=0,"Likely","Target"),IF(DB_Colleges!Y11>=0.4,CHOOSE(W17+2,"Reach","Target","Likely"),IF(W17=1,"Target","Reach"))))))) -> Likely | F17: =IF(OR(B17="",NOT(ISNUMBER(DB_Colleges!Y11))),"",DB_Colleges!Y11) -> 0.99 | G17: =IF(OR(B17="",NOT(ISNUMBER(DB_Colleges!Z11))),"",DB_Colleges!Z11&"-"&DB_Colleges!AA11) -> 800-1060 | H17: =IF(OR(B17="",NOT(ISNUMBER(DB_Colleges!AD11))),"",DB_Colleges!AD11) | I17: =IF(B17="","",IF(COUNT(DB_Colleges!I11:O11)=0,IF(DB_Colleges!P11="Yes","Rolling","Check site"),MIN(DB_Colleges!I11:O11))) -> 46492 | J17: =IF(OR(B17="",COUNT(DB_Colleges!I11:O11)=0),"",INDEX({"ED","ED II","EA","EA II","REA","RD","Priority"},MATCH(MIN(DB_Colleges!I11:O11),DB_Colleges!I11:O11,0))) -> Priority | K17: =IF(OR(B17="",NOT(ISNUMBER(DB_Colleges!N11))),"",DB_Colleges!N11) -> 46568 | L17: =IF(B17="","",DB_Colleges!G11&"") -> School portal | M17: =IF(OR(B17="",NOT(ISNUMBER(DB_Colleges!S11))),"",DB_Colleges!S11) -> 40 | N17: =IF(B17="","",DB_Colleges!U11&"") -> Required | O17: =IF(B17="","",IF(ISNUMBER(DB_Colleges!AH11),DB_Colleges!AH11,"Check")) -> Check | P17: =IF(B17="","",DB_Colleges!W11&"") -> Not required | Q17: =IF(OR(B17="",NOT(ISNUMBER(DB_Colleges!AF11))),"",DB_Colleges!AF11) | R17: =IF(OR(B17="",NOT(ISNUMBER(DB_Colleges!AG11))),"",DB_Colleges!AG11) | S17: =IF(B17="","",DB_Colleges!AK11&"") -> Mixed | T17: =IF(B17="","",DB_Colleges!AI11&"") -> https://www.columbusstate.edu/admissions/undergraduate/first-time-freshmen.php | U17: =IF(AND(ISNUMBER($X$4),ISNUMBER(DB_Colleges!Z11),ISNUMBER(DB_Colleges!AA11)),IF($X$4>=DB_Colleges!AA11,1,IF($X$4<DB_Colleges!Z11,-1,0)),"") -> 0 | V17: =IF(AND(ISNUMBER($Y$4),ISNUMBER(DB_Colleges!AD11)),IF($Y$4>=DB_Colleges!AD11+0.15,1,IF($Y$4<DB_Colleges!AD11-0.2,-1,0)),"") | W17: =IF(COUNT(U17:V17)=0,0,MIN(U17:V17)) -> 0
A18: =IF(B18="","",IF(COUNTIF('My Colleges'!$B$8:$B$27,B18)>0,"On list","")) | B18: =IF(DB_Colleges!A12="","",DB_Colleges!A12) -> Georgia Southwestern State University | C18: =IF(B18="","",DB_Colleges!B12) -> Georgia Public (USG) | D18: =IF(B18="","",DB_Colleges!C12&", "&DB_Colleges!D12) -> Americus, GA | E18: =IF(B18="","",IF(AND(NOT(ISNUMBER($X$4)),NOT(ISNUMBER($Y$4))),"Add scores",IF(NOT(ISNUMBER(DB_Colleges!Y12)),IF(OR(C18="Ivy League",C18="Highly Selective"),"Reach",IF(COUNT(U18:V18)=0,"No data",CHOOSE(W18+2,"Reach","Target","Likely"))),IF(DB_Colleges!Y12<0.15,"Reach",IF(DB_Colleges!Y12>=0.75,IF(W18>=0,"Likely","Target"),IF(DB_Colleges!Y12>=0.4,CHOOSE(W18+2,"Reach","Target","Likely"),IF(W18=1,"Target","Reach"))))))) -> Target | F18: =IF(OR(B18="",NOT(ISNUMBER(DB_Colleges!Y12))),"",DB_Colleges!Y12) -> 0.75 | G18: =IF(OR(B18="",NOT(ISNUMBER(DB_Colleges!Z12))),"",DB_Colleges!Z12&"-"&DB_Colleges!AA12) -> 890-1110 | H18: =IF(OR(B18="",NOT(ISNUMBER(DB_Colleges!AD12))),"",DB_Colleges!AD12) | I18: =IF(B18="","",IF(COUNT(DB_Colleges!I12:O12)=0,IF(DB_Colleges!P12="Yes","Rolling","Check site"),MIN(DB_Colleges!I12:O12))) -> Rolling | J18: =IF(OR(B18="",COUNT(DB_Colleges!I12:O12)=0),"",INDEX({"ED","ED II","EA","EA II","REA","RD","Priority"},MATCH(MIN(DB_Colleges!I12:O12),DB_Colleges!I12:O12,0))) | K18: =IF(OR(B18="",NOT(ISNUMBER(DB_Colleges!N12))),"",DB_Colleges!N12) | L18: =IF(B18="","",DB_Colleges!G12&"") -> GAfutures; School portal | M18: =IF(OR(B18="",NOT(ISNUMBER(DB_Colleges!S12))),"",DB_Colleges!S12) | N18: =IF(B18="","",DB_Colleges!U12&"") -> Optional | O18: =IF(B18="","",IF(ISNUMBER(DB_Colleges!AH12),DB_Colleges!AH12,"Check")) -> Check | P18: =IF(B18="","",DB_Colleges!W12&"") -> Not required | Q18: =IF(OR(B18="",NOT(ISNUMBER(DB_Colleges!AF12))),"",DB_Colleges!AF12) | R18: =IF(OR(B18="",NOT(ISNUMBER(DB_Colleges!AG12))),"",DB_Colleges!AG12) | S18: =IF(B18="","",DB_Colleges!AK12&"") -> Mixed | T18: =IF(B18="","",DB_Colleges!AI12&"") -> https://www.gsw.edu/admissions/undergraduate/freshman | U18: =IF(AND(ISNUMBER($X$4),ISNUMBER(DB_Colleges!Z12),ISNUMBER(DB_Colleges!AA12)),IF($X$4>=DB_Colleges!AA12,1,IF($X$4<DB_Colleges!Z12,-1,0)),"") -> -1 | V18: =IF(AND(ISNUMBER($Y$4),ISNUMBER(DB_Colleges!AD12)),IF($Y$4>=DB_Colleges!AD12+0.15,1,IF($Y$4<DB_Colleges!AD12-0.2,-1,0)),"") | W18: =IF(COUNT(U18:V18)=0,0,MIN(U18:V18)) -> -1
A19: =IF(B19="","",IF(COUNTIF('My Colleges'!$B$8:$B$27,B19)>0,"On list","")) | B19: =IF(DB_Colleges!A13="","",DB_Colleges!A13) -> Clayton State University | C19: =IF(B19="","",DB_Colleges!B13) -> Georgia Public (USG) | D19: =IF(B19="","",DB_Colleges!C13&", "&DB_Colleges!D13) -> Morrow, GA | E19: =IF(B19="","",IF(AND(NOT(ISNUMBER($X$4)),NOT(ISNUMBER($Y$4))),"Add scores",IF(NOT(ISNUMBER(DB_Colleges!Y13)),IF(OR(C19="Ivy League",C19="Highly Selective"),"Reach",IF(COUNT(U19:V19)=0,"No data",CHOOSE(W19+2,"Reach","Target","Likely"))),IF(DB_Colleges!Y13<0.15,"Reach",IF(DB_Colleges!Y13>=0.75,IF(W19>=0,"Likely","Target"),IF(DB_Colleges!Y13>=0.4,CHOOSE(W19+2,"Reach","Target","Likely"),IF(W19=1,"Target","Reach"))))))) -> Reach | F19: =IF(OR(B19="",NOT(ISNUMBER(DB_Colleges!Y13))),"",DB_Colleges!Y13) -> 0.68 | G19: =IF(OR(B19="",NOT(ISNUMBER(DB_Colleges!Z13))),"",DB_Colleges!Z13&"-"&DB_Colleges!AA13) -> 860-1078 | H19: =IF(OR(B19="",NOT(ISNUMBER(DB_Colleges!AD13))),"",DB_Colleges!AD13) | I19: =IF(B19="","",IF(COUNT(DB_Colleges!I13:O13)=0,IF(DB_Colleges!P13="Yes","Rolling","Check site"),MIN(DB_Colleges!I13:O13))) -> Rolling | J19: =IF(OR(B19="",COUNT(DB_Colleges!I13:O13)=0),"",INDEX({"ED","ED II","EA","EA II","REA","RD","Priority"},MATCH(MIN(DB_Colleges!I13:O13),DB_Colleges!I13:O13,0))) | K19: =IF(OR(B19="",NOT(ISNUMBER(DB_Colleges!N13))),"",DB_Colleges!N13) | L19: =IF(B19="","",DB_Colleges!G13&"") -> Common App; School portal | M19: =IF(OR(B19="",NOT(ISNUMBER(DB_Colleges!S13))),"",DB_Colleges!S13) -> 40 | N19: =IF(B19="","",DB_Colleges!U13&"") -> Optional | O19: =IF(B19="","",IF(ISNUMBER(DB_Colleges!AH13),DB_Colleges!AH13,"Check")) -> Check | P19: =IF(B19="","",DB_Colleges!W13&"") -> Not required | Q19: =IF(OR(B19="",NOT(ISNUMBER(DB_Colleges!AF13))),"",DB_Colleges!AF13) | R19: =IF(OR(B19="",NOT(ISNUMBER(DB_Colleges!AG13))),"",DB_Colleges!AG13) | S19: =IF(B19="","",DB_Colleges!AK13&"") -> Aggregator only | T19: =IF(B19="","",DB_Colleges!AI13&"") -> https://www.clayton.edu/admissions/undergrad/freshman.php | U19: =IF(AND(ISNUMBER($X$4),ISNUMBER(DB_Colleges!Z13),ISNUMBER(DB_Colleges!AA13)),IF($X$4>=DB_Colleges!AA13,1,IF($X$4<DB_Colleges!Z13,-1,0)),"") -> -1 | V19: =IF(AND(ISNUMBER($Y$4),ISNUMBER(DB_Colleges!AD13)),IF($Y$4>=DB_Colleges!AD13+0.15,1,IF($Y$4<DB_Colleges!AD13-0.2,-1,0)),"") | W19: =IF(COUNT(U19:V19)=0,0,MIN(U19:V19)) -> -1
... A406: =IF(B406="","",IF(COUNTIF('My Colleges'!$B$8:$B$27,B406)>0,"On list","")) | B406: =IF(DB_Colleges!A400="","",DB_Colleges!A400) | C406: =IF(B406="","",DB_Colleges!B400) | D406: =IF(B406="","",DB_Colleges!C400&", "&DB_Colleges!D400) | E406: =IF(B406="","",IF(AND(NOT(ISNUMBER($X$4)),NOT(ISNUMBER($Y$4))),"Add scores",IF(NOT(ISNUMBER(DB_Colleges!Y400)),IF(OR(C406="Ivy League",C406="Highly Selective"),"Reach",IF(COUNT(U406:V406)=0,"No data",CHOOSE(W406+2,"Reach","Target","Likely"))),IF(DB_Colleges!Y400<0.15,"Reach",IF(DB_Colleges!Y400>=0.75,IF(W406>=0,"Likely","Target"),IF(DB_Colleges!Y400>=0.4,CHOOSE(W406+2,"Reach","Target","Likely"),IF(W406=1,"Target","Reach"))))))) | F406: =IF(OR(B406="",NOT(ISNUMBER(DB_Colleges!Y400))),"",DB_Colleges!Y400) | G406: =IF(OR(B406="",NOT(ISNUMBER(DB_Colleges!Z400))),"",DB_Colleges!Z400&"-"&DB_Colleges!AA400) | H406: =IF(OR(B406="",NOT(ISNUMBER(DB_Colleges!AD400))),"",DB_Colleges!AD400) | I406: =IF(B406="","",IF(COUNT(DB_Colleges!I400:O400)=0,IF(DB_Colleges!P400="Yes","Rolling","Check site"),MIN(DB_Colleges!I400:O400))) | J406: =IF(OR(B406="",COUNT(DB_Colleges!I400:O400)=0),"",INDEX({"ED","ED II","EA","EA II","REA","RD","Priority"},MATCH(MIN(DB_Colleges!I400:O400),DB_Colleges!I400:O400,0))) | K406: =IF(OR(B406="",NOT(ISNUMBER(DB_Colleges!N400))),"",DB_Colleges!N400) | L406: =IF(B406="","",DB_Colleges!G400&"") | M406: =IF(OR(B406="",NOT(ISNUMBER(DB_Colleges!S400))),"",DB_Colleges!S400) | N406: =IF(B406="","",DB_Colleges!U400&"") | O406: =IF(B406="","",IF(ISNUMBER(DB_Colleges!AH400),DB_Colleges!AH400,"Check")) | P406: =IF(B406="","",DB_Colleges!W400&"") | Q406: =IF(OR(B406="",NOT(ISNUMBER(DB_Colleges!AF400))),"",DB_Colleges!AF400) | R406: =IF(OR(B406="",NOT(ISNUMBER(DB_Colleges!AG400))),"",DB_Colleges!AG400) | S406: =IF(B406="","",DB_Colleges!AK400&"") | T406: =IF(B406="","",DB_Colleges!AI400&"") | U406: =IF(AND(ISNUMBER($X$4),ISNUMBER(DB_Colleges!Z400),ISNUMBER(DB_Colleges!AA400)),IF($X$4>=DB_Colleges!AA400,1,IF($X$4<DB_Colleges!Z400,-1,0)),"") | V406: =IF(AND(ISNUMBER($Y$4),ISNUMBER(DB_Colleges!AD400)),IF($Y$4>=DB_Colleges!AD400+0.15,1,IF($Y$4<DB_Colleges!AD400-0.2,-1,0)),"") | W406: =IF(COUNT(U406:V406)=0,0,MIN(U406:V406)) -> 0

Sheet My Colleges
A1: My Colleges
A2: Pick each college from the dropdown in column B (or type one that is not listed), then choose your round in column E. Everything gray fills in by itself. Aim for a balanced list: about 2 Likely, 3 to 4 Target, 2 Reach.
B4: Colleges on my list | D4: Likely / Target / Reach | F4: Next filing date | H4: Days until next | I4: Submitted | K4: Admitted | M4: Dates not verified
B5: =COUNTIFS(B8:B27,"?*",V8:V27,"<>No") -> 0 | D5: =COUNTIFS(D8:D27,"Likely",V8:V27,"<>No")&" / "&COUNTIFS(D8:D27,"Target",V8:V27,"<>No")&" / "&COUNTIFS(D8:D27,"Reach",V8:V27,"<>No") -> 0 / 0 / 0 | F5: =IF(COUNTIFS(I8:I27,">="&TODAY(),T8:T27,"<>Submitted",T8:T27,"<>Complete in portal",V8:V27,"<>No")=0,"",_xlfn.MINIFS(I8:I27,I8:I27,">="&TODAY(),T8:T27,"<>Submitted",T8:T27,"<>Complete in portal",V8:V27,"<>No")) | H5: =IF(F5="","",F5-TODAY()) | I5: =COUNTIF(T8:T27,"Submitted")+COUNTIF(T8:T27,"Complete in portal") -> 0 | K5: =COUNTIF(U8:U27,"Admitted") -> 0 | M5: =COUNTIFS(B8:B27,"?*",W8:W27,"<>Yes",V8:V27,"<>No") -> 0
A7: # | B7: College | C7: In Database? | D7: Fit | E7: Round | F7: Deadline for My Round | G7: My Deadline (only if not listed or Rolling) | H7: Scholarship (Merit) Deadline | I7: Effective Filing Date | J7: Days Out | K7: How to Apply | L7: App Fee | M7: Fee Waiver? | N7: Test Policy | O7: Recommendations | P7: Extra Essays | Q7: Steps Done | R7: Next Step | S7: Next Step Due | T7: Status | U7: Decision | V7: On Final List | W7: Deadline Verified | X7: Watch For | Y7: Notes | AA7: m | AB7: css | AC7: interview | AD7: data status | AE7: common app | AF7: platform
A8: 1 | C8: =IF($B8="","",IF(($AA8=0),"No: fill G","Yes")) | D8: =IF(($AA8=0),"",INDEX(Explore!$E$8:$E$406,$AA8)) | F8: =IF($B8="","",IF($E8="","Pick a round",IF($E8="Rolling","Rolling",IF(($AA8=0),"",IF(COUNT(INDEX(DB_Colleges!$I$2:$O$400,$AA8,0))=0,"No date on file",IF(ISNUMBER(INDEX(DB_Colleges!$I$2:$O$400,$AA8,MATCH($E8,{"ED","ED II","EA","EA II","REA","RD","Priority"},0))),INDEX(DB_Colleges!$I$2:$O$400,$AA8,MATCH($E8,{"ED","ED II","EA","EA II","REA","RD","Priority"},0)),"Not offered")))))) | H8: =IF(($AA8=0),"",IF(ISNUMBER(INDEX(DB_Colleges!$Q$2:$Q$400,$AA8)),INDEX(DB_Colleges!$Q$2:$Q$400,$AA8),"")) | I8: =IF($B8="","",IF(ISNUMBER($G8),IF(ISNUMBER($H8),MIN($G8,$H8),$G8),IF(ISNUMBER($F8),IF(ISNUMBER($H8),MIN($F8,$H8),$F8),IF(AND($E8="Rolling",ISNUMBER($H8)),$H8,"")))) | J8: =IF(AND(ISNUMBER($I8),$T8<>"Submitted",$T8<>"Complete in portal"),$I8-TODAY(),"") | K8: =IF(($AA8=0),"",INDEX(DB_Colleges!$G$2:$G$400,$AA8)&"") | L8: =IF(($AA8=0),"",IF(ISNUMBER(INDEX(DB_Colleges!$S$2:$S$400,$AA8)),INDEX(DB_Colleges!$S$2:$S$400,$AA8),"")) | N8: =IF(($AA8=0),"",INDEX(DB_Colleges!$U$2:$U$400,$AA8)&"") | O8: =IF(($AA8=0),"",INDEX(DB_Colleges!$V$2:$V$400,$AA8)&"") | P8: =IF(($AA8=0),"",IF(ISNUMBER(INDEX(DB_Colleges!$AH$2:$AH$400,$AA8)),INDEX(DB_Colleges!$AH$2:$AH$400,$AA8),"Check")) | Q8: =IF($B8="","",'Next Steps'!$AA8&" of "&'Next Steps'!$AB8) | R8: =IF($B8="","",'Next Steps'!$AC8) | S8: =IF($B8="","",'Next Steps'!$AD8) | X8: =IF($B8="","",IF($V8="No","Dropped from your list.",IF(AND(OR($E8="ED",$E8="ED II"),OR(ISNUMBER($F8),ISNUMBER($G8))),"BINDING: if admitted you must attend. ","")&IF(AND(OR($E8="ED",$E8="ED II"),ISNUMBER($F8),SUMPRODUCT((($E$8:$E$27="ED")+($E$8:$E$27="ED II"))*ISNUMBER($F$8:$F$27)*($V$8:$V$27<>"No"))>1),"Only one Early Decision can be active at a time. ","")&IF($E8="REA","Restrictive Early Action: limits other private early applications. ","")&IF(AND(OR($E8="REA",$E8="ED"),ISNUMBER($F8),SUMPRODUCT(($E$8:$E$27="REA")*ISNUMBER($F$8:$F$27)*($V$8:$V$27<>"No"))>0,SUMPRODUCT((($E$8:$E$27="ED")+($E$8:$E$27="ED II"))*ISNUMBER($F$8:$F$27)*($V$8:$V$27<>"No"))>0),"You have Restrictive Early Action and Early Decision at the same time: check the REA college's rules, this is usually not allowed. ","")&IF($F8="Not offered","This college does not offer that round: pick another. ","")&IF(AND($E8="Rolling",NOT(ISNUMBER($G8))),"Rolling: set a target date in column G. ","")&IF(AND(NOT(($AA8=0)),NOT(ISNUMBER($F8)),NOT(ISNUMBER($G8)),$E8<>"",$E8<>"Rolling",$F8<>"Not offered"),"No date on file yet: find it on the college site and type it in column G. ","")&IF(AND(ISNUMBER($H8),ISNUMBER($I8),$H8=$I8,ISNUMBER($F8),$H8<$F8),"Scholarship deadline is earlier than the application deadline, so it is your real deadline. ","")&IF($AE8="No","Not on Common App: apply on "&$AF8&". ","")&IF(($AA8=0),"Not in the database: type the deadline in column G and check requirements on the college site. ","")&IF(AND(NOT(($AA8=0)),$W8<>"Yes",$AD8<>"Official 2026-27"),"Date not yet confirmed: check the college site, then set Deadline Verified to Yes. ","")&IF(LEFT($AB8,8)="Required",IF($AB8="Required","CSS Profile required. ","CSS Profile may be required: check the college's aid page. "),"")&IF($AC8<>"","Interview: "&$AC8&". Watch your email, including spam, and reply the same day. ",""))) | AA8: =IF($B8="",0,IFERROR(MATCH($B8,DB_Colleges!$A$2:$A$400,0),0)) -> 0 | AB8: =IF(($AA8=0),"",INDEX(DB_Colleges!$W$2:$W$400,$AA8)&"") | AC8: =IF(($AA8=0),"",IF(OR(LEFT(INDEX(DB_Colleges!$X$2:$X$400,$AA8)&"",4)="None",LEFT(INDEX(DB_Colleges!$X$2:$X$400,$AA8)&"",3)="No ",LEFT(INDEX(DB_Colleges!$X$2:$X$400,$AA8)&"",3)="Not"),"",INDEX(DB_Colleges!$X$2:$X$400,$AA8)&"")) | AD8: =IF(($AA8=0),"",INDEX(DB_Colleges!$AK$2:$AK$400,$AA8)&"") | AE8: =IF(($AA8=0),"",INDEX(DB_Colleges!$H$2:$H$400,$AA8)&"") | AF8: =IF(($AA8=0),"",INDEX(DB_Colleges!$G$2:$G$400,$AA8)&"")
A9: 2 | C9: =IF($B9="","",IF(($AA9=0),"No: fill G","Yes")) | D9: =IF(($AA9=0),"",INDEX(Explore!$E$8:$E$406,$AA9)) | F9: =IF($B9="","",IF($E9="","Pick a round",IF($E9="Rolling","Rolling",IF(($AA9=0),"",IF(COUNT(INDEX(DB_Colleges!$I$2:$O$400,$AA9,0))=0,"No date on file",IF(ISNUMBER(INDEX(DB_Colleges!$I$2:$O$400,$AA9,MATCH($E9,{"ED","ED II","EA","EA II","REA","RD","Priority"},0))),INDEX(DB_Colleges!$I$2:$O$400,$AA9,MATCH($E9,{"ED","ED II","EA","EA II","REA","RD","Priority"},0)),"Not offered")))))) | H9: =IF(($AA9=0),"",IF(ISNUMBER(INDEX(DB_Colleges!$Q$2:$Q$400,$AA9)),INDEX(DB_Colleges!$Q$2:$Q$400,$AA9),"")) | I9: =IF($B9="","",IF(ISNUMBER($G9),IF(ISNUMBER($H9),MIN($G9,$H9),$G9),IF(ISNUMBER($F9),IF(ISNUMBER($H9),MIN($F9,$H9),$F9),IF(AND($E9="Rolling",ISNUMBER($H9)),$H9,"")))) | J9: =IF(AND(ISNUMBER($I9),$T9<>"Submitted",$T9<>"Complete in portal"),$I9-TODAY(),"") | K9: =IF(($AA9=0),"",INDEX(DB_Colleges!$G$2:$G$400,$AA9)&"") | L9: =IF(($AA9=0),"",IF(ISNUMBER(INDEX(DB_Colleges!$S$2:$S$400,$AA9)),INDEX(DB_Colleges!$S$2:$S$400,$AA9),"")) | N9: =IF(($AA9=0),"",INDEX(DB_Colleges!$U$2:$U$400,$AA9)&"") | O9: =IF(($AA9=0),"",INDEX(DB_Colleges!$V$2:$V$400,$AA9)&"") | P9: =IF(($AA9=0),"",IF(ISNUMBER(INDEX(DB_Colleges!$AH$2:$AH$400,$AA9)),INDEX(DB_Colleges!$AH$2:$AH$400,$AA9),"Check")) | Q9: =IF($B9="","",'Next Steps'!$AA9&" of "&'Next Steps'!$AB9) | R9: =IF($B9="","",'Next Steps'!$AC9) | S9: =IF($B9="","",'Next Steps'!$AD9) | X9: =IF($B9="","",IF($V9="No","Dropped from your list.",IF(AND(OR($E9="ED",$E9="ED II"),OR(ISNUMBER($F9),ISNUMBER($G9))),"BINDING: if admitted you must attend. ","")&IF(AND(OR($E9="ED",$E9="ED II"),ISNUMBER($F9),SUMPRODUCT((($E$8:$E$27="ED")+($E$8:$E$27="ED II"))*ISNUMBER($F$8:$F$27)*($V$8:$V$27<>"No"))>1),"Only one Early Decision can be active at a time. ","")&IF($E9="REA","Restrictive Early Action: limits other private early applications. ","")&IF(AND(OR($E9="REA",$E9="ED"),ISNUMBER($F9),SUMPRODUCT(($E$8:$E$27="REA")*ISNUMBER($F$8:$F$27)*($V$8:$V$27<>"No"))>0,SUMPRODUCT((($E$8:$E$27="ED")+($E$8:$E$27="ED II"))*ISNUMBER($F$8:$F$27)*($V$8:$V$27<>"No"))>0),"You have Restrictive Early Action and Early Decision at the same time: check the REA college's rules, this is usually not allowed. ","")&IF($F9="Not offered","This college does not offer that round: pick another. ","")&IF(AND($E9="Rolling",NOT(ISNUMBER($G9))),"Rolling: set a target date in column G. ","")&IF(AND(NOT(($AA9=0)),NOT(ISNUMBER($F9)),NOT(ISNUMBER($G9)),$E9<>"",$E9<>"Rolling",$F9<>"Not offered"),"No date on file yet: find it on the college site and type it in column G. ","")&IF(AND(ISNUMBER($H9),ISNUMBER($I9),$H9=$I9,ISNUMBER($F9),$H9<$F9),"Scholarship deadline is earlier than the application deadline, so it is your real deadline. ","")&IF($AE9="No","Not on Common App: apply on "&$AF9&". ","")&IF(($AA9=0),"Not in the database: type the deadline in column G and check requirements on the college site. ","")&IF(AND(NOT(($AA9=0)),$W9<>"Yes",$AD9<>"Official 2026-27"),"Date not yet confirmed: check the college site, then set Deadline Verified to Yes. ","")&IF(LEFT($AB9,8)="Required",IF($AB9="Required","CSS Profile required. ","CSS Profile may be required: check the college's aid page. "),"")&IF($AC9<>"","Interview: "&$AC9&". Watch your email, including spam, and reply the same day. ",""))) | AA9: =IF($B9="",0,IFERROR(MATCH($B9,DB_Colleges!$A$2:$A$400,0),0)) -> 0 | AB9: =IF(($AA9=0),"",INDEX(DB_Colleges!$W$2:$W$400,$AA9)&"") | AC9: =IF(($AA9=0),"",IF(OR(LEFT(INDEX(DB_Colleges!$X$2:$X$400,$AA9)&"",4)="None",LEFT(INDEX(DB_Colleges!$X$2:$X$400,$AA9)&"",3)="No ",LEFT(INDEX(DB_Colleges!$X$2:$X$400,$AA9)&"",3)="Not"),"",INDEX(DB_Colleges!$X$2:$X$400,$AA9)&"")) | AD9: =IF(($AA9=0),"",INDEX(DB_Colleges!$AK$2:$AK$400,$AA9)&"") | AE9: =IF(($AA9=0),"",INDEX(DB_Colleges!$H$2:$H$400,$AA9)&"") | AF9: =IF(($AA9=0),"",INDEX(DB_Colleges!$G$2:$G$400,$AA9)&"")
A10: 3 | C10: =IF($B10="","",IF(($AA10=0),"No: fill G","Yes")) | D10: =IF(($AA10=0),"",INDEX(Explore!$E$8:$E$406,$AA10)) | F10: =IF($B10="","",IF($E10="","Pick a round",IF($E10="Rolling","Rolling",IF(($AA10=0),"",IF(COUNT(INDEX(DB_Colleges!$I$2:$O$400,$AA10,0))=0,"No date on file",IF(ISNUMBER(INDEX(DB_Colleges!$I$2:$O$400,$AA10,MATCH($E10,{"ED","ED II","EA","EA II","REA","RD","Priority"},0))),INDEX(DB_Colleges!$I$2:$O$400,$AA10,MATCH($E10,{"ED","ED II","EA","EA II","REA","RD","Priority"},0)),"Not offered")))))) | H10: =IF(($AA10=0),"",IF(ISNUMBER(INDEX(DB_Colleges!$Q$2:$Q$400,$AA10)),INDEX(DB_Colleges!$Q$2:$Q$400,$AA10),"")) | I10: =IF($B10="","",IF(ISNUMBER($G10),IF(ISNUMBER($H10),MIN($G10,$H10),$G10),IF(ISNUMBER($F10),IF(ISNUMBER($H10),MIN($F10,$H10),$F10),IF(AND($E10="Rolling",ISNUMBER($H10)),$H10,"")))) | J10: =IF(AND(ISNUMBER($I10),$T10<>"Submitted",$T10<>"Complete in portal"),$I10-TODAY(),"") | K10: =IF(($AA10=0),"",INDEX(DB_Colleges!$G$2:$G$400,$AA10)&"") | L10: =IF(($AA10=0),"",IF(ISNUMBER(INDEX(DB_Colleges!$S$2:$S$400,$AA10)),INDEX(DB_Colleges!$S$2:$S$400,$AA10),"")) | N10: =IF(($AA10=0),"",INDEX(DB_Colleges!$U$2:$U$400,$AA10)&"") | O10: =IF(($AA10=0),"",INDEX(DB_Colleges!$V$2:$V$400,$AA10)&"") | P10: =IF(($AA10=0),"",IF(ISNUMBER(INDEX(DB_Colleges!$AH$2:$AH$400,$AA10)),INDEX(DB_Colleges!$AH$2:$AH$400,$AA10),"Check")) | Q10: =IF($B10="","",'Next Steps'!$AA10&" of "&'Next Steps'!$AB10) | R10: =IF($B10="","",'Next Steps'!$AC10) | S10: =IF($B10="","",'Next Steps'!$AD10) | X10: =IF($B10="","",IF($V10="No","Dropped from your list.",IF(AND(OR($E10="ED",$E10="ED II"),OR(ISNUMBER($F10),ISNUMBER($G10))),"BINDING: if admitted you must attend. ","")&IF(AND(OR($E10="ED",$E10="ED II"),ISNUMBER($F10),SUMPRODUCT((($E$8:$E$27="ED")+($E$8:$E$27="ED II"))*ISNUMBER($F$8:$F$27)*($V$8:$V$27<>"No"))>1),"Only one Early Decision can be active at a time. ","")&IF($E10="REA","Restrictive Early Action: limits other private early applications. ","")&IF(AND(OR($E10="REA",$E10="ED"),ISNUMBER($F10),SUMPRODUCT(($E$8:$E$27="REA")*ISNUMBER($F$8:$F$27)*($V$8:$V$27<>"No"))>0,SUMPRODUCT((($E$8:$E$27="ED")+($E$8:$E$27="ED II"))*ISNUMBER($F$8:$F$27)*($V$8:$V$27<>"No"))>0),"You have Restrictive Early Action and Early Decision at the same time: check the REA college's rules, this is usually not allowed. ","")&IF($F10="Not offered","This college does not offer that round: pick another. ","")&IF(AND($E10="Rolling",NOT(ISNUMBER($G10))),"Rolling: set a target date in column G. ","")&IF(AND(NOT(($AA10=0)),NOT(ISNUMBER($F10)),NOT(ISNUMBER($G10)),$E10<>"",$E10<>"Rolling",$F10<>"Not offered"),"No date on file yet: find it on the college site and type it in column G. ","")&IF(AND(ISNUMBER($H10),ISNUMBER($I10),$H10=$I10,ISNUMBER($F10),$H10<$F10),"Scholarship deadline is earlier than the application deadline, so it is your real deadline. ","")&IF($AE10="No","Not on Common App: apply on "&$AF10&". ","")&IF(($AA10=0),"Not in the database: type the deadline in column G and check requirements on the college site. ","")&IF(AND(NOT(($AA10=0)),$W10<>"Yes",$AD10<>"Official 2026-27"),"Date not yet confirmed: check the college site, then set Deadline Verified to Yes. ","")&IF(LEFT($AB10,8)="Required",IF($AB10="Required","CSS Profile required. ","CSS Profile may be required: check the college's aid page. "),"")&IF($AC10<>"","Interview: "&$AC10&". Watch your email, including spam, and reply the same day. ",""))) | AA10: =IF($B10="",0,IFERROR(MATCH($B10,DB_Colleges!$A$2:$A$400,0),0)) -> 0 | AB10: =IF(($AA10=0),"",INDEX(DB_Colleges!$W$2:$W$400,$AA10)&"") | AC10: =IF(($AA10=0),"",IF(OR(LEFT(INDEX(DB_Colleges!$X$2:$X$400,$AA10)&"",4)="None",LEFT(INDEX(DB_Colleges!$X$2:$X$400,$AA10)&"",3)="No ",LEFT(INDEX(DB_Colleges!$X$2:$X$400,$AA10)&"",3)="Not"),"",INDEX(DB_Colleges!$X$2:$X$400,$AA10)&"")) | AD10: =IF(($AA10=0),"",INDEX(DB_Colleges!$AK$2:$AK$400,$AA10)&"") | AE10: =IF(($AA10=0),"",INDEX(DB_Colleges!$H$2:$H$400,$AA10)&"") | AF10: =IF(($AA10=0),"",INDEX(DB_Colleges!$G$2:$G$400,$AA10)&"")
A11: 4 | C11: =IF($B11="","",IF(($AA11=0),"No: fill G","Yes")) | D11: =IF(($AA11=0),"",INDEX(Explore!$E$8:$E$406,$AA11)) | F11: =IF($B11="","",IF($E11="","Pick a round",IF($E11="Rolling","Rolling",IF(($AA11=0),"",IF(COUNT(INDEX(DB_Colleges!$I$2:$O$400,$AA11,0))=0,"No date on file",IF(ISNUMBER(INDEX(DB_Colleges!$I$2:$O$400,$AA11,MATCH($E11,{"ED","ED II","EA","EA II","REA","RD","Priority"},0))),INDEX(DB_Colleges!$I$2:$O$400,$AA11,MATCH($E11,{"ED","ED II","EA","EA II","REA","RD","Priority"},0)),"Not offered")))))) | H11: =IF(($AA11=0),"",IF(ISNUMBER(INDEX(DB_Colleges!$Q$2:$Q$400,$AA11)),INDEX(DB_Colleges!$Q$2:$Q$400,$AA11),"")) | I11: =IF($B11="","",IF(ISNUMBER($G11),IF(ISNUMBER($H11),MIN($G11,$H11),$G11),IF(ISNUMBER($F11),IF(ISNUMBER($H11),MIN($F11,$H11),$F11),IF(AND($E11="Rolling",ISNUMBER($H11)),$H11,"")))) | J11: =IF(AND(ISNUMBER($I11),$T11<>"Submitted",$T11<>"Complete in portal"),$I11-TODAY(),"") | K11: =IF(($AA11=0),"",INDEX(DB_Colleges!$G$2:$G$400,$AA11)&"") | L11: =IF(($AA11=0),"",IF(ISNUMBER(INDEX(DB_Colleges!$S$2:$S$400,$AA11)),INDEX(DB_Colleges!$S$2:$S$400,$AA11),"")) | N11: =IF(($AA11=0),"",INDEX(DB_Colleges!$U$2:$U$400,$AA11)&"") | O11: =IF(($AA11=0),"",INDEX(DB_Colleges!$V$2:$V$400,$AA11)&"") | P11: =IF(($AA11=0),"",IF(ISNUMBER(INDEX(DB_Colleges!$AH$2:$AH$400,$AA11)),INDEX(DB_Colleges!$AH$2:$AH$400,$AA11),"Check")) | Q11: =IF($B11="","",'Next Steps'!$AA11&" of "&'Next Steps'!$AB11) | R11: =IF($B11="","",'Next Steps'!$AC11) | S11: =IF($B11="","",'Next Steps'!$AD11) | X11: =IF($B11="","",IF($V11="No","Dropped from your list.",IF(AND(OR($E11="ED",$E11="ED II"),OR(ISNUMBER($F11),ISNUMBER($G11))),"BINDING: if admitted you must attend. ","")&IF(AND(OR($E11="ED",$E11="ED II"),ISNUMBER($F11),SUMPRODUCT((($E$8:$E$27="ED")+($E$8:$E$27="ED II"))*ISNUMBER($F$8:$F$27)*($V$8:$V$27<>"No"))>1),"Only one Early Decision can be active at a time. ","")&IF($E11="REA","Restrictive Early Action: limits other private early applications. ","")&IF(AND(OR($E11="REA",$E11="ED"),ISNUMBER($F11),SUMPRODUCT(($E$8:$E$27="REA")*ISNUMBER($F$8:$F$27)*($V$8:$V$27<>"No"))>0,SUMPRODUCT((($E$8:$E$27="ED")+($E$8:$E$27="ED II"))*ISNUMBER($F$8:$F$27)*($V$8:$V$27<>"No"))>0),"You have Restrictive Early Action and Early Decision at the same time: check the REA college's rules, this is usually not allowed. ","")&IF($F11="Not offered","This college does not offer that round: pick another. ","")&IF(AND($E11="Rolling",NOT(ISNUMBER($G11))),"Rolling: set a target date in column G. ","")&IF(AND(NOT(($AA11=0)),NOT(ISNUMBER($F11)),NOT(ISNUMBER($G11)),$E11<>"",$E11<>"Rolling",$F11<>"Not offered"),"No date on file yet: find it on the college site and type it in column G. ","")&IF(AND(ISNUMBER($H11),ISNUMBER($I11),$H11=$I11,ISNUMBER($F11),$H11<$F11),"Scholarship deadline is earlier than the application deadline, so it is your real deadline. ","")&IF($AE11="No","Not on Common App: apply on "&$AF11&". ","")&IF(($AA11=0),"Not in the database: type the deadline in column G and check requirements on the college site. ","")&IF(AND(NOT(($AA11=0)),$W11<>"Yes",$AD11<>"Official 2026-27"),"Date not yet confirmed: check the college site, then set Deadline Verified to Yes. ","")&IF(LEFT($AB11,8)="Required",IF($AB11="Required","CSS Profile required. ","CSS Profile may be required: check the college's aid page. "),"")&IF($AC11<>"","Interview: "&$AC11&". Watch your email, including spam, and reply the same day. ",""))) | AA11: =IF($B11="",0,IFERROR(MATCH($B11,DB_Colleges!$A$2:$A$400,0),0)) -> 0 | AB11: =IF(($AA11=0),"",INDEX(DB_Colleges!$W$2:$W$400,$AA11)&"") | AC11: =IF(($AA11=0),"",IF(OR(LEFT(INDEX(DB_Colleges!$X$2:$X$400,$AA11)&"",4)="None",LEFT(INDEX(DB_Colleges!$X$2:$X$400,$AA11)&"",3)="No ",LEFT(INDEX(DB_Colleges!$X$2:$X$400,$AA11)&"",3)="Not"),"",INDEX(DB_Colleges!$X$2:$X$400,$AA11)&"")) | AD11: =IF(($AA11=0),"",INDEX(DB_Colleges!$AK$2:$AK$400,$AA11)&"") | AE11: =IF(($AA11=0),"",INDEX(DB_Colleges!$H$2:$H$400,$AA11)&"") | AF11: =IF(($AA11=0),"",INDEX(DB_Colleges!$G$2:$G$400,$AA11)&"")
